Workbook

Sheet Read Me
B1: Read Me - 2027 Operations cost plan
B2: Monthly cost plan Jan-Dec 2027 for the Retail Energy & Utilities Operations team. All amounts in EUR.
B5: 1. How the workbook works
B6: Flow | C6: Inputs -> Calculations -> Summary. Personnel feeds the Summary directly. You only type in Inputs and Personnel; Calculations and Summary are formulas only.
B7: Months | C7: Every sheet uses the same 12 monthly columns (Jan-27 to Dec-27) followed by a Total 2027 column.
B8: Single plan | C8: One set of assumptions (no Base/Low/High). To test a what-if, change an input cell; to keep a version, save a copy of the file.
B10: 2. Sheets
B11: Read Me | C11: This page.
B12: Summary | C12: The cost plan. Cost lines grouped in 6 blocks (Payments & collections, Customer communications, Customer service, CS platform, Platforms & market services, Personnel), each with a subtotal, then TOTAL OPERATIONS COST. Key figures at the bottom: new and active customers, total payments, cost per active customer per month, personnel FTE. Below: fixed/variable split, cost by bucket (CTS, outside CTS) and unit economics per POD.
B13: Inputs | C13: All non-personnel assumptions. Section A: monthly inputs (new customers, CS platform licences). Section B: assumptions, one value per cell, each with unit and note / source. Also shows the check of new customers vs the 2,000 target.
B14: Calculations | C14: Line-by-line monthly volumes and costs. For each line the volume row comes first, then the cost row, so every number on the Summary can be traced back to its driver.
B15: Personnel | C15: One row per person or role (up to 40 rows). Monthly FTE and monthly cost are calculated from dates, FTE and quarterly cost. Totals by department at the bottom feed the Summary.
B16: Lists | C16: Department list used by the dropdown on Personnel.
B18: 3. Colour code
B19: Blue text | C19: Input - you can change it.
B20: Yellow fill | C20: Input not yet available - enter the value. A blank input counts as 0, so the related cost shows as '-'.
B21: Black text | C21: Formula - do not overwrite.
B22: Green text | C22: Link to another sheet - do not overwrite.
B23: '-' | C23: Zero value.
B25: 4. How to update the plan
B26: Step 1 - Customers | C26: Inputs row 6: enter new customers per month. Opening base on 1 Jan 2027 is 0. Check 'Difference vs target' in section B: 0 means the months add up to the 2,000 target.
B27: Step 2 - Assumptions | C27: Inputs section B: fill the yellow cells and update any value that changes (rates, shares, prices).
B28: Step 3 - Licences | C28: Inputs row 7: number of CS platform licences per month (starts at 3).
B29: Step 4 - Personnel | C29: Personnel sheet: one row per person/role - ID, role, department (dropdown), start date, end date (blank = open), FTE, quarterly cost at 1 FTE taken from the HR analysis, one-off hiring fee. Check 'unassigned cost' at the bottom is 0.
B30: Step 5 - Read | C30: Summary sheet: monthly and full-year cost by line, block and total.
B32: 5. Calculation logic
B33: Customers | C33: Active customers = active last month + new customers this month. PODs = active customers x 1.
B34: Payments | C34: Payments = active customers x 1 (monthly) + new customers x 1 (starting payment) -> 13 payments for a customer active all year. Split by payment mix: SEPA DD and Card / Apple Pay / Google Pay (card share = 100% - SEPA share).
B35: Payment commissions | C35: SEPA: transactions x fee per transaction (fixed + % x average payment, capped if a cap is set). Card / wallet: transactions x (EUR 0.25 + 1.7% x average payment).
B36: Stripe Billing | C36: Part of payment retries: retried payments x average payment x 0.7% (Smart Retries). Not applied to first-attempt payments.
B37: Payment retries | C37: Failed payments = transactions x failure rate. SEPA: failures x EUR 3.50 + retries x SEPA fee. Card / wallet: retries x card fee. Plus Stripe Billing 0.7% on the retried volume. Retries per failure = 1 by default.
B38: Paper invoices | C38: Invoices = active customers x 1. Paper invoices = invoices x paper share; cost = printing & enveloping + postage per paper invoice. Post and paper invoices are the same line.
B39: SMS | C39: Active customers x SMS per customer x price per SMS.
B40: Inbound calls | C40: Inbound calls = active customers x calls per customer, split into 3 paths: (1) AI = calls x AI share; (2) direct to human = calls x human share; (3) no human, no AI = the rest (100% - AI - human).
B41: Call costs | C41: Cost of contact EUR 0.89 on paths 1 and 3. AI call EUR 1.99 on path 1 (on top of the cost of contact). Human calls = path 2 + AI calls escalated to a human (AI calls x escalation %): human minutes = calls x average duration, cost = minutes x inbound price + minutes x recordings & transcripts price (no cost of contact). An escalated call pays EUR 0.89 + EUR 1.99 + its human minutes.
B42: Outbound calls | C42: Active customers x outbound calls per customer x average duration x EUR 0.15 per minute.
B43: Disputes | C43: Active customers x dispute rate x cost per dispute (EUR 0 in 2027).
B44: CS platform | C44: Licences x monthly licence price + number of phone numbers x monthly fee per number.
... B46: Personnel | C46: Monthly FTE = FTE x share of the month between start and end date (calendar days). Monthly cost = quarterly cost / 3 x monthly FTE, plus the hiring fee in the start month.
B48: 6. Key assumptions and sources
...

Sheet Summary
A1: 2027 Operations cost plan - Summary (EUR)
A2: Monthly view Jan-Dec 2027. All figures calculated from Inputs, Calculations and Personnel - do not type in this sheet.
A4: Cost line | C4: Jan-27 | D4: Feb-27 | E4: Mar-27 | F4: Apr-27 | G4: May-27 | H4: Jun-27 | I4: Jul-27 | J4: Aug-27 | K4: Sep-27 | L4: Oct-27 | M4: Nov-27 | N4: Dec-27 | O4: Total 2027 | P4: CTS bucket | Q4: Fixed / Variable
A5: 1. Payments & collections
A6: SEPA DD commissions | C6: =Calculations!C19 -> 0 | D6: =Calculations!D19 -> 0 | E6: =Calculations!E19 -> 0 | F6: =Calculations!F19 -> 0 | G6: =Calculations!G19 -> 0 | H6: =Calculations!H19 -> 0 | I6: =Calculations!I19 -> 179.487 | J6: =Calculations!J19 -> 269.2305 | ... O6: =Calculations!O19 -> 2424.1525 | P6: CTS - Operations | Q6: Variable
A7: Card / wallet commissions | C7: =Calculations!C20 -> 0 | D7: =Calculations!D20 -> 0 | E7: =Calculations!E20 -> 0 | F7: =Calculations!F20 -> 0 | G7: =Calculations!G20 -> 0 | H7: =Calculations!H20 -> 0 | I7: =Calculations!I20 -> 298.701 | J7: =Calculations!J20 -> 448.0515 | ... O7: =Calculations!O20 -> 4034.2575 | P7: CTS - Operations | Q7: Variable
A8: Payment retries - transaction fees | C8: =Calculations!C28 -> 0 | D8: =Calculations!D28 -> 0 | E8: =Calculations!E28 -> 0 | F8: =Calculations!F28 -> 0 | G8: =Calculations!G28 -> 0 | H8: =Calculations!H28 -> 0 | I8: =Calculations!I28 -> 101.70486 | J8: =Calculations!J28 -> 152.55729 | ... O8: =Calculations!O28 -> 1373.6265 | P8: CTS - Operations | Q8: Variable
A9: Payment retries - Stripe Billing | C9: =Calculations!C30 -> 0 | D9: =Calculations!D30 -> 0 | E9: =Calculations!E30 -> 0 | F9: =Calculations!F30 -> 0 | G9: =Calculations!G30 -> 0 | H9: =Calculations!H30 -> 0 | I9: =Calculations!I30 -> 19.02096 | J9: =Calculations!J30 -> 28.53144 | ... O9: =Calculations!O30 -> 256.8972 | P9: CTS - Operations | Q9: Variable
A10: Subtotal Payments & collections | C10: =SUM(C6:C9) -> 0 | D10: =SUM(D6:D9) -> 0 | E10: =SUM(E6:E9) -> 0 | F10: =SUM(F6:F9) -> 0 | G10: =SUM(G6:G9) -> 0 | H10: =SUM(H6:H9) -> 0 | I10: =SUM(I6:I9) -> 598.91382 | J10: =SUM(J6:J9) -> 898.37073 | ... O10: =SUM(O6:O9) -> 8088.9336
A12: 2. Customer communications
A13: Paper invoices - printing & enveloping | C13: =Calculations!C36 -> 0 | D13: =Calculations!D36 -> 0 | E13: =Calculations!E36 -> 0 | F13: =Calculations!F36 -> 0 | G13: =Calculations!G36 -> 0 | H13: =Calculations!H36 -> 0 | I13: =Calculations!I36 -> 33.3 | J13: =Calculations!J36 -> 66.6 | ... O13: =Calculations!O36 -> 699.5 | P13: CTS - Operations | Q13: Variable
A14: Paper invoices - postage | C14: =Calculations!C37 -> 0 | D14: =Calculations!D37 -> 0 | E14: =Calculations!E37 -> 0 | F14: =Calculations!F37 -> 0 | G14: =Calculations!G37 -> 0 | H14: =Calculations!H37 -> 0 | I14: =Calculations!I37 -> 66.6 | J14: =Calculations!J37 -> 133.2 | ... O14: =Calculations!O37 -> 1399 | P14: CTS - Operations | Q14: Variable
A15: SMS | C15: =Calculations!C39 -> 0 | D15: =Calculations!D39 -> 0 | E15: =Calculations!E39 -> 0 | F15: =Calculations!F39 -> 0 | G15: =Calculations!G39 -> 0 | H15: =Calculations!H39 -> 0 | I15: =Calculations!I39 -> 0 | J15: =Calculations!J39 -> 0 | ... O15: =Calculations!O39 -> 0 | P15: CTS - Operations | Q15: Variable
A16: Subtotal Customer communications | C16: =SUM(C13:C15) -> 0 | D16: =SUM(D13:D15) -> 0 | E16: =SUM(E13:E15) -> 0 | F16: =SUM(F13:F15) -> 0 | G16: =SUM(G13:G15) -> 0 | H16: =SUM(H13:H15) -> 0 | I16: =SUM(I13:I15) -> 99.9 | J16: =SUM(J13:J15) -> 199.8 | ... O16: =SUM(O13:O15) -> 2098.5
A18: 3. Customer service
A19: Cost of contact (AI + no human) | C19: =Calculations!C49 -> 0 | D19: =Calculations!D49 -> 0 | E19: =Calculations!E49 -> 0 | F19: =Calculations!F49 -> 0 | G19: =Calculations!G49 -> 0 | H19: =Calculations!H49 -> 0 | I19: =Calculations!I49 -> 711.288 | J19: =Calculations!J49 -> 1422.576 | ... O19: =Calculations!O49 -> 14941.32 | P19: CTS - Customer care | Q19: Variable
A20: AI calls | C20: =Calculations!C50 -> 0 | D20: =Calculations!D50 -> 0 | E20: =Calculations!E50 -> 0 | F20: =Calculations!F50 -> 0 | G20: =Calculations!G50 -> 0 | H20: =Calculations!H50 -> 0 | I20: =Calculations!I50 -> 1192.806 | J20: =Calculations!J50 -> 2385.612 | ... O20: =Calculations!O50 -> 25056.09 | P20: CTS - Customer care | Q20: Variable
A21: Inbound calls - human | C21: =Calculations!C51 -> 0 | D21: =Calculations!D51 -> 0 | E21: =Calculations!E51 -> 0 | F21: =Calculations!F51 -> 0 | G21: =Calculations!G51 -> 0 | H21: =Calculations!H51 -> 0 | I21: =Calculations!I51 -> 37.20276 | J21: =Calculations!J51 -> 74.40552 | ... O21: =Calculations!O51 -> 781.4814 | P21: CTS - Customer care | Q21: Variable
A22: Recordings & transcripts | C22: =Calculations!C52 -> 0 | D22: =Calculations!D52 -> 0 | E22: =Calculations!E52 -> 0 | F22: =Calculations!F52 -> 0 | G22: =Calculations!G52 -> 0 | H22: =Calculations!H52 -> 0 | I22: =Calculations!I52 -> 8.237754 | J22: =Calculations!J52 -> 16.475508 | ... O22: =Calculations!O52 -> 173.04231 | P22: CTS - Customer care | Q22: Variable
A23: Outbound calls | C23: =Calculations!C54 -> 0 | D23: =Calculations!D54 -> 0 | E23: =Calculations!E54 -> 0 | F23: =Calculations!F54 -> 0 | G23: =Calculations!G54 -> 0 | H23: =Calculations!H54 -> 0 | I23: =Calculations!I54 -> 0 | J23: =Calculations!J54 -> 0 | ... O23: =Calculations!O54 -> 0 | P23: CTS - Customer care | Q23: Variable
A24: Dispute resolution | C24: =Calculations!C56 -> 0 | D24: =Calculations!D56 -> 0 | E24: =Calculations!E56 -> 0 | F24: =Calculations!F56 -> 0 | G24: =Calculations!G56 -> 0 | H24: =Calculations!H56 -> 0 | I24: =Calculations!I56 -> 0 | J24: =Calculations!J56 -> 0 | ... O24: =Calculations!O56 -> 0 | P24: CTS - Customer care | Q24: Variable
A25: Subtotal Customer service | C25: =SUM(C19:C24) -> 0 | D25: =SUM(D19:D24) -> 0 | E25: =SUM(E19:E24) -> 0 | F25: =SUM(F19:F24) -> 0 | G25: =SUM(G19:G24) -> 0 | H25: =SUM(H19:H24) -> 0 | I25: =SUM(I19:I24) -> 1949.5345 | J25: =SUM(J19:J24) -> 3899.069 | ... O25: =SUM(O19:O24) -> 40951.934
A27: 4. CS platform
A28: CS platform licences | C28: =Calculations!C60 -> 80 | D28: =Calculations!D60 -> 80 | E28: =Calculations!E60 -> 80 | F28: =Calculations!F60 -> 80 | G28: =Calculations!G60 -> 240 | H28: =Calculations!H60 -> 240 | I28: =Calculations!I60 -> 240 | J28: =Calculations!J60 -> 240 | ... O28: =Calculations!O60 -> 2240 | P28: CTS - Customer care | Q28: Fixed
A29: Phone numbers | C29: =Calculations!C61 -> 2 | D29: =Calculations!D61 -> 2 | E29: =Calculations!E61 -> 2 | F29: =Calculations!F61 -> 2 | G29: =Calculations!G61 -> 2 | H29: =Calculations!H61 -> 2 | I29: =Calculations!I61 -> 2 | J29: =Calculations!J61 -> 2 | ... O29: =Calculations!O61 -> 24 | P29: CTS - Customer care | Q29: Fixed
A30: Subtotal CS platform | C30: =SUM(C28:C29) -> 82 | D30: =SUM(D28:D29) -> 82 | E30: =SUM(E28:E29) -> 82 | F30: =SUM(F28:F29) -> 82 | G30: =SUM(G28:G29) -> 242 | H30: =SUM(H28:H29) -> 242 | I30: =SUM(I28:I29) -> 242 | J30: =SUM(J28:J29) -> 242 | ... O30: =SUM(O28:O29) -> 2264
A32: 5. Platforms & market services
A33: Haulogy - POD fees | C33: =Calculations!C65 -> 0 | D33: =Calculations!D65 -> 0 | E33: =Calculations!E65 -> 0 | F33: =Calculations!F65 -> 0 | G33: =Calculations!G65 -> 0 | H33: =Calculations!H65 -> 0 | I33: =Calculations!I65 -> 999 | J33: =Calculations!J65 -> 1998 | ... O33: =Calculations!O65 -> 20985 | P33: CTS - Operations | Q33: Variable
A34: Haulogy - fixed monthly fee | C34: =Calculations!C66 -> 8334 | D34: =Calculations!D66 -> 8334 | E34: =Calculations!E66 -> 8334 | F34: =Calculations!F66 -> 8334 | G34: =Calculations!G66 -> 8334 | H34: =Calculations!H66 -> 8334 | I34: =Calculations!I66 -> 8334 | J34: =Calculations!J66 -> 8334 | ... O34: =Calculations!O66 -> 100008 | P34: CTS - Operations | Q34: Fixed
A35: Pricing connector platform | C35: =Calculations!C68 -> 666.66667 | D35: =Calculations!D68 -> 666.66667 | E35: =Calculations!E68 -> 666.66667 | F35: =Calculations!F68 -> 666.66667 | G35: =Calculations!G68 -> 666.66667 | H35: =Calculations!H68 -> 666.66667 | I35: =Calculations!I68 -> 666.66667 | J35: =Calculations!J68 -> 666.66667 | ... O35: =Calculations!O68 -> 8000 | P35: Outside CTS | Q35: Fixed
A36: Equifax - customer checks | C36: =Calculations!C67 -> 0 | D36: =Calculations!D67 -> 0 | E36: =Calculations!E67 -> 0 | F36: =Calculations!F67 -> 0 | G36: =Calculations!G67 -> 0 | H36: =Calculations!H67 -> 0 | I36: =Calculations!I67 -> 333 | J36: =Calculations!J67 -> 333 | ... O36: =Calculations!O67 -> 2000 | P36: CTS - Operations | Q36: Variable
A37: Subtotal Platforms & market services | C37: =SUM(C33:C36) -> 9000.6667 | D37: =SUM(D33:D36) -> 9000.6667 | E37: =SUM(E33:E36) -> 9000.6667 | F37: =SUM(F33:F36) -> 9000.6667 | G37: =SUM(G33:G36) -> 9000.6667 | H37: =SUM(H33:H36) -> 9000.6667 | I37: =SUM(I33:I36) -> 10332.667 | J37: =SUM(J33:J36) -> 11331.667 | ... O37: =SUM(O33:O36) -> 130993
A39: 6. Personnel
A40: =Lists!A4 -> Operations & Service | C40: =Personnel!V53 -> 53391.667 | D40: =Personnel!W53 -> 42391.667 | E40: =Personnel!X53 -> 42391.667 | F40: =Personnel!Y53 -> 42391.667 | G40: =Personnel!Z53 -> 42391.667 | H40: =Personnel!AA53 -> 42391.667 | I40: =Personnel!AB53 -> 42391.667 | J40: =Personnel!AC53 -> 42391.667 | ... N40: =Personnel!AG53 -> 42391.667 | O40: =SUM(C40:N40) -> 519700 | P40: CTS - Operations | Q40: Fixed
A41: =Lists!A2 -> Billing & Invoicing | C41: =Personnel!V51 -> 5583.3333 | D41: =Personnel!W51 -> 5583.3333 | E41: =Personnel!X51 -> 5583.3333 | F41: =Personnel!Y51 -> 12953.333 | G41: =Personnel!Z51 -> 12953.333 | H41: =Personnel!AA51 -> 12953.333 | I41: =Personnel!AB51 -> 12953.333 | J41: =Personnel!AC51 -> 12953.333 | ... N41: =Personnel!AG51 -> 12953.333 | O41: =SUM(C41:N41) -> 133330 | P41: CTS - Operations | Q41: Fixed
A42: =Lists!A3 -> Customer Service | C42: =Personnel!V52 -> 4243.3333 | D42: =Personnel!W52 -> 4243.3333 | E42: =Personnel!X52 -> 4243.3333 | F42: =Personnel!Y52 -> 22618.333 | G42: =Personnel!Z52 -> 12618.333 | H42: =Personnel!AA52 -> 12618.333 | I42: =Personnel!AB52 -> 12618.333 | J42: =Personnel!AC52 -> 12618.333 | ... N42: =Personnel!AG52 -> 12618.333 | O42: =SUM(C42:N42) -> 136295 | P42: CTS - Customer care | Q42: Fixed
A43: =Lists!A5 -> Pricing & Risk Management | C43: =Personnel!V54 -> 6476.6667 | D43: =Personnel!W54 -> 6476.6667 | E43: =Personnel!X54 -> 6476.6667 | F43: =Personnel!Y54 -> 12060 | G43: =Personnel!Z54 -> 12060 | H43: =Personnel!AA54 -> 12060 | I43: =Personnel!AB54 -> 12060 | J43: =Personnel!AC54 -> 12060 | ... N43: =Personnel!AG54 -> 12060 | O43: =SUM(C43:N43) -> 127970 | P43: Outside CTS | Q43: Fixed
A44: =Lists!A6 -> Switching & Metering | C44: =Personnel!V55 -> 9603.3333 | D44: =Personnel!W55 -> 9603.3333 | E44: =Personnel!X55 -> 9603.3333 | F44: =Personnel!Y55 -> 9603.3333 | G44: =Personnel!Z55 -> 9603.3333 | H44: =Personnel!AA55 -> 9603.3333 | I44: =Personnel!AB55 -> 9603.3333 | J44: =Personnel!AC55 -> 9603.3333 | ... N44: =Personnel!AG55 -> 9603.3333 | O44: =SUM(C44:N44) -> 115240 | P44: CTS - Operations | Q44: Fixed
A45: Subtotal Personnel | C45: =SUM(C40:C44) -> 79298.333 | D45: =SUM(D40:D44) -> 68298.333 | E45: =SUM(E40:E44) -> 68298.333 | F45: =SUM(F40:F44) -> 99626.667 | G45: =SUM(G40:G44) -> 89626.667 | H45: =SUM(H40:H44) -> 89626.667 | I45: =SUM(I40:I44) -> 89626.667 | J45: =SUM(J40:J44) -> 89626.667 | ... O45: =SUM(O40:O44) -> 1032535
A47: TOTAL OPERATIONS COST | C47: =C10+C16+C25+C30+C37+C45 -> 88381 | D47: =D10+D16+D25+D30+D37+D45 -> 77381 | E47: =E10+E16+E25+E30+E37+E45 -> 77381 | F47: =F10+F16+F25+F30+F37+F45 -> 108709.33 | G47: =G10+G16+G25+G30+G37+G45 -> 98869.333 | H47: =H10+H16+H25+H30+H37+H45 -> 98869.333 | I47: =I10+I16+I25+I30+I37+I45 -> 102849.68 | J47: =J10+J16+J25+J30+J37+J45 -> 106197.57 | ... O47: =O10+O16+O25+O30+O37+O45 -> 1216931.4
...

Sheet Inputs
A1: Inputs - 2027 Operations cost plan
A2: All non-personnel assumptions. Blue text = input. Yellow fill = value not yet available (enter it; blank counts as 0). Black = calculated.
A4: A. Monthly inputs
A5: Input | B5: Unit | C5: Jan-27 | D5: Feb-27 | E5: Mar-27 | F5: Apr-27 | G5: May-27 | H5: Jun-27 | I5: Jul-27 | J5: Aug-27 | K5: Sep-27 | L5: Oct-27 | M5: Nov-27 | N5: Dec-27 | O5: Total 2027 | P5: Note / source
A6: New customers | B6: customers | C6: 0 | D6: 0 | E6: 0 | F6: 0 | G6: 0 | H6: 0 | I6: 333 | J6: 333 | K6: 333 | L6: 333 | M6: 333 | N6: 335 | O6: =SUM(C6:N6) -> 2000 | P6: Placeholder 200/month (Luca) - replace with real phasing. Opening base 1 Jan 2027 = 0.
A7: CS platform licences | B7: licences | C7: 1 | D7: 1 | E7: 1 | F7: 1 | G7: 3 | H7: 3 | I7: 3 | J7: 3 | K7: 3 | L7: 3 | M7: 3 | N7: 3 | P7: Initial estimate: 3 licences (Luca)
A9: B. Assumptions
A10: Input | B10: Unit | C10: Value | D10: Note / source
A11: Customer base
A12: Year-end customer target (= PODs) | B12: customers | C12: 2000 | D12: 2027 year-end target (Luca)
A13: Total new customers entered (row 6) | B13: customers | C13: =O6 -> 2000 | D13: Calculated
A14: Difference vs target | B14: customers | C14: =$C$13-$C$12 -> 0 | D14: Calculated: 0 = monthly phasing matches the target
A16: Payments - volumes
A17: Payments per active customer per month | B17: payments | C17: 1 | D17: Monthly billing (Luca)
A18: Starting payments per new customer | B18: payments | C18: 1 | D18: One starting payment at sign-up -> 13 payments in a full year (Luca)
A19: Average payment amount | B19: EUR | C19: 100 | D19: Luca
A20: Payment mix - SEPA Direct Debit | B20: % of payments | C20: 0.77 | D20: Input
A21: Payment mix - Card / Apple Pay / Google Pay | B21: % of payments | C21: =1-$C$20 -> 0.23 | D21: Calculated as 100% minus SEPA share
A23: Payments - Stripe rates
A24: SEPA DD - fixed fee per successful transaction | B24: EUR / tx | C24: 0.35 | D24: Stripe, flat EUR 0.35 (Luca). Alternative pricing seen: 0.8% + EUR 0.30 capped EUR 6 - use the % and cap cells below if that applies
A25: SEPA DD - variable fee | B25: % of amount | C25: 0 | D25: Stripe - 0 under flat pricing
A26: SEPA DD - fee cap per transaction | B26: EUR / tx | C26: 0 | D26: Stripe - 0 = no cap
A27: SEPA DD - fee per transaction (calculated) | B27: EUR / tx | C27: =IF($C$26>0,MIN($C$24+$C$25*$C$19,$C$26),$C$24+$C$25*$C$19) -> 0.35 | D27: Fixed + % x average amount, capped if a cap is set
A28: SEPA DD - fee per failed / returned debit | B28: EUR / failure | C28: 3.5 | D28: Stripe (Luca)
A29: Card / wallet - variable fee | B29: % of amount | C29: 0.017 | D29: Blended assumption: Stripe standard EEA cards 1.5% and premium 1.9% -> 1.7% assumes ~50/50 split. Apple Pay / Google Pay priced as cards
A30: Card / wallet - fixed fee per transaction | B30: EUR / tx | C30: 0.25 | D30: Stripe (Luca)
A31: Card / wallet - fee per transaction (calculated) | B31: EUR / tx | C31: =$C$30+$C$29*$C$19 -> 1.95 | D31: Fixed + % x average amount
A32: Stripe Billing fee (Smart Retries) | B32: % of retried volume | C32: 0.007 | D32: Applied to the volume of retried payments only (Luca). Rate source: metacto.com cost breakdown of Stripe Billing (secondary source) - confirm with Stripe
A34: Payments - retries
A35: Failure rate - SEPA DD | B35: % of SEPA tx | C35: 0.05 | D35: Input
A36: Failure rate - Card / wallet | B36: % of card tx | C36: 0.01 | D36: Input
A37: Retries per failed payment | B37: retries | C37: 1 | D37: Default 1. Each retry is charged as a new transaction (SEPA: new collection fee; card: card fee, assumed charged on retry)
A39: Customer communications
A40: Invoices per active customer per month | B40: invoices | C40: 1 | D40: Monthly billing
A41: Paper invoice share | B41: % of invoices | C41: 0.2 | D41: Input
A42: Printing & enveloping per paper invoice | B42: EUR / invoice | C42: 0.5 | D42: Input
A43: Postage per paper invoice | B43: EUR / invoice | C43: 1 | D43: Input
A44: SMS per active customer per month | B44: SMS | C44: 0 | D44: Input
A45: Price per SMS | B45: EUR / SMS | C45: 0 | D45: Input
A47: Customer service
...

Sheet Calculations
A1: Calculations - monthly volumes and costs (EUR)
A2: No inputs on this sheet. Every line reads from Inputs or Personnel.
A4: Line | B4: Unit | C4: Jan-27 | D4: Feb-27 | E4: Mar-27 | F4: Apr-27 | G4: May-27 | H4: Jun-27 | I4: Jul-27 | J4: Aug-27 | K4: Sep-27 | L4: Oct-27 | M4: Nov-27 | N4: Dec-27 | O4: Total 2027
A5: Month number | B5: month no. | C5: 1 | D5: 2 | E5: 3 | F5: 4 | G5: 5 | H5: 6 | I5: 7 | J5: 8 | K5: 9 | L5: 10 | M5: 11 | N5: 12
A7: Customer base
A8: New customers | B8: customers | C8: =Inputs!C6 -> 0 | D8: =Inputs!D6 -> 0 | E8: =Inputs!E6 -> 0 | F8: =Inputs!F6 -> 0 | G8: =Inputs!G6 -> 0 | H8: =Inputs!H6 -> 0 | I8: =Inputs!I6 -> 333 | J8: =Inputs!J6 -> 333 | ... N8: =Inputs!N6 -> 335 | O8: =SUM(C8:N8) -> 2000
A9: Active customers (end of month) | B9: customers | C9: =C8 -> 0 | D9: =C9+D8 -> 0 | E9: =D9+E8 -> 0 | F9: =E9+F8 -> 0 | G9: =F9+G8 -> 0 | H9: =G9+H8 -> 0 | I9: =H9+I8 -> 333 | J9: =I9+J8 -> 666 | K9: =J9+K8 -> 999 | ... N9: =M9+N8 -> 2000 | O9: =N9 -> 2000
A11: Payments - volumes
A12: Monthly payments | B12: payments | C12: =C9*Inputs!$C$17 -> 0 | D12: =D9*Inputs!$C$17 -> 0 | E12: =E9*Inputs!$C$17 -> 0 | F12: =F9*Inputs!$C$17 -> 0 | G12: =G9*Inputs!$C$17 -> 0 | H12: =H9*Inputs!$C$17 -> 0 | I12: =I9*Inputs!$C$17 -> 333 | J12: =J9*Inputs!$C$17 -> 666 | ... N12: =N9*Inputs!$C$17 -> 2000 | O12: =SUM(C12:N12) -> 6995
A13: Starting payments (new customers) | B13: payments | C13: =C8*Inputs!$C$18 -> 0 | D13: =D8*Inputs!$C$18 -> 0 | E13: =E8*Inputs!$C$18 -> 0 | F13: =F8*Inputs!$C$18 -> 0 | G13: =G8*Inputs!$C$18 -> 0 | H13: =H8*Inputs!$C$18 -> 0 | I13: =I8*Inputs!$C$18 -> 333 | J13: =J8*Inputs!$C$18 -> 333 | ... N13: =N8*Inputs!$C$18 -> 335 | O13: =SUM(C13:N13) -> 2000
A14: Total payments | B14: payments | C14: =C12+C13 -> 0 | D14: =D12+D13 -> 0 | E14: =E12+E13 -> 0 | F14: =F12+F13 -> 0 | G14: =G12+G13 -> 0 | H14: =H12+H13 -> 0 | I14: =I12+I13 -> 666 | J14: =J12+J13 -> 999 | ... N14: =N12+N13 -> 2335 | O14: =SUM(C14:N14) -> 8995
A15: SEPA DD transactions | B15: payments | C15: =C14*Inputs!$C$20 -> 0 | D15: =D14*Inputs!$C$20 -> 0 | E15: =E14*Inputs!$C$20 -> 0 | F15: =F14*Inputs!$C$20 -> 0 | G15: =G14*Inputs!$C$20 -> 0 | H15: =H14*Inputs!$C$20 -> 0 | I15: =I14*Inputs!$C$20 -> 512.82 | J15: =J14*Inputs!$C$20 -> 769.23 | ... N15: =N14*Inputs!$C$20 -> 1797.95 | O15: =SUM(C15:N15) -> 6926.15
A16: Card / wallet transactions | B16: payments | C16: =C14*Inputs!$C$21 -> 0 | D16: =D14*Inputs!$C$21 -> 0 | E16: =E14*Inputs!$C$21 -> 0 | F16: =F14*Inputs!$C$21 -> 0 | G16: =G14*Inputs!$C$21 -> 0 | H16: =H14*Inputs!$C$21 -> 0 | I16: =I14*Inputs!$C$21 -> 153.18 | J16: =J14*Inputs!$C$21 -> 229.77 | ... N16: =N14*Inputs!$C$21 -> 537.05 | O16: =SUM(C16:N16) -> 2068.85
A18: Payments - costs
A19: SEPA DD commissions | B19: EUR | C19: =C15*Inputs!$C$27 -> 0 | D19: =D15*Inputs!$C$27 -> 0 | E19: =E15*Inputs!$C$27 -> 0 | F19: =F15*Inputs!$C$27 -> 0 | G19: =G15*Inputs!$C$27 -> 0 | H19: =H15*Inputs!$C$27 -> 0 | I19: =I15*Inputs!$C$27 -> 179.487 | J19: =J15*Inputs!$C$27 -> 269.2305 | ... N19: =N15*Inputs!$C$27 -> 629.2825 | O19: =SUM(C19:N19) -> 2424.1525
A20: Card / wallet commissions | B20: EUR | C20: =C16*Inputs!$C$31 -> 0 | D20: =D16*Inputs!$C$31 -> 0 | E20: =E16*Inputs!$C$31 -> 0 | F20: =F16*Inputs!$C$31 -> 0 | G20: =G16*Inputs!$C$31 -> 0 | H20: =H16*Inputs!$C$31 -> 0 | I20: =I16*Inputs!$C$31 -> 298.701 | J20: =J16*Inputs!$C$31 -> 448.0515 | ... N20: =N16*Inputs!$C$31 -> 1047.2475 | O20: =SUM(C20:N20) -> 4034.2575
A22: Payment retries
A23: Failed SEPA DD payments | B23: payments | C23: =C15*Inputs!$C$35 -> 0 | D23: =D15*Inputs!$C$35 -> 0 | E23: =E15*Inputs!$C$35 -> 0 | F23: =F15*Inputs!$C$35 -> 0 | G23: =G15*Inputs!$C$35 -> 0 | H23: =H15*Inputs!$C$35 -> 0 | I23: =I15*Inputs!$C$35 -> 25.641 | J23: =J15*Inputs!$C$35 -> 38.4615 | ... N23: =N15*Inputs!$C$35 -> 89.8975 | O23: =SUM(C23:N23) -> 346.3075
A24: Failed card / wallet payments | B24: payments | C24: =C16*Inputs!$C$36 -> 0 | D24: =D16*Inputs!$C$36 -> 0 | E24: =E16*Inputs!$C$36 -> 0 | F24: =F16*Inputs!$C$36 -> 0 | G24: =G16*Inputs!$C$36 -> 0 | H24: =H16*Inputs!$C$36 -> 0 | I24: =I16*Inputs!$C$36 -> 1.5318 | J24: =J16*Inputs!$C$36 -> 2.2977 | ... N24: =N16*Inputs!$C$36 -> 5.3705 | O24: =SUM(C24:N24) -> 20.6885
A25: SEPA DD failure fees | B25: EUR | C25: =C23*Inputs!$C$28 -> 0 | D25: =D23*Inputs!$C$28 -> 0 | E25: =E23*Inputs!$C$28 -> 0 | F25: =F23*Inputs!$C$28 -> 0 | G25: =G23*Inputs!$C$28 -> 0 | H25: =H23*Inputs!$C$28 -> 0 | I25: =I23*Inputs!$C$28 -> 89.7435 | J25: =J23*Inputs!$C$28 -> 134.61525 | ... N25: =N23*Inputs!$C$28 -> 314.64125 | O25: =SUM(C25:N25) -> 1212.0763
A26: SEPA DD retry collection fees | B26: EUR | C26: =C23*Inputs!$C$37*Inputs!$C$27 -> 0 | D26: =D23*Inputs!$C$37*Inputs!$C$27 -> 0 | E26: =E23*Inputs!$C$37*Inputs!$C$27 -> 0 | F26: =F23*Inputs!$C$37*Inputs!$C$27 -> 0 | G26: =G23*Inputs!$C$37*Inputs!$C$27 -> 0 | H26: =H23*Inputs!$C$37*Inputs!$C$27 -> 0 | I26: =I23*Inputs!$C$37*Inputs!$C$27 -> 8.97435 | J26: =J23*Inputs!$C$37*Inputs!$C$27 -> 13.461525 | ... N26: =N23*Inputs!$C$37*Inputs!$C$27 -> 31.464125 | O26: =SUM(C26:N26) -> 121.20763
A27: Card / wallet retry fees | B27: EUR | C27: =C24*Inputs!$C$37*Inputs!$C$31 -> 0 | D27: =D24*Inputs!$C$37*Inputs!$C$31 -> 0 | E27: =E24*Inputs!$C$37*Inputs!$C$31 -> 0 | F27: =F24*Inputs!$C$37*Inputs!$C$31 -> 0 | G27: =G24*Inputs!$C$37*Inputs!$C$31 -> 0 | H27: =H24*Inputs!$C$37*Inputs!$C$31 -> 0 | I27: =I24*Inputs!$C$37*Inputs!$C$31 -> 2.98701 | J27: =J24*Inputs!$C$37*Inputs!$C$31 -> 4.480515 | ... N27: =N24*Inputs!$C$37*Inputs!$C$31 -> 10.472475 | O27: =SUM(C27:N27) -> 40.342575
A28: Retry transaction fees | B28: EUR | C28: =C25+C26+C27 -> 0 | D28: =D25+D26+D27 -> 0 | E28: =E25+E26+E27 -> 0 | F28: =F25+F26+F27 -> 0 | G28: =G25+G26+G27 -> 0 | H28: =H25+H26+H27 -> 0 | I28: =I25+I26+I27 -> 101.70486 | J28: =J25+J26+J27 -> 152.55729 | ... N28: =N25+N26+N27 -> 356.57785 | O28: =SUM(C28:N28) -> 1373.6265
A29: Retried volume | B29: EUR | C29: =(C23+C24)*Inputs!$C$37*Inputs!$C$19 -> 0 | D29: =(D23+D24)*Inputs!$C$37*Inputs!$C$19 -> 0 | E29: =(E23+E24)*Inputs!$C$37*Inputs!$C$19 -> 0 | F29: =(F23+F24)*Inputs!$C$37*Inputs!$C$19 -> 0 | G29: =(G23+G24)*Inputs!$C$37*Inputs!$C$19 -> 0 | H29: =(H23+H24)*Inputs!$C$37*Inputs!$C$19 -> 0 | I29: =(I23+I24)*Inputs!$C$37*Inputs!$C$19 -> 2717.28 | J29: =(J23+J24)*Inputs!$C$37*Inputs!$C$19 -> 4075.92 | ... N29: =(N23+N24)*Inputs!$C$37*Inputs!$C$19 -> 9526.8 | O29: =SUM(C29:N29) -> 36699.6
A30: Stripe Billing (Smart Retries) | B30: EUR | C30: =C29*Inputs!$C$32 -> 0 | D30: =D29*Inputs!$C$32 -> 0 | E30: =E29*Inputs!$C$32 -> 0 | F30: =F29*Inputs!$C$32 -> 0 | G30: =G29*Inputs!$C$32 -> 0 | H30: =H29*Inputs!$C$32 -> 0 | I30: =I29*Inputs!$C$32 -> 19.02096 | J30: =J29*Inputs!$C$32 -> 28.53144 | ... N30: =N29*Inputs!$C$32 -> 66.6876 | O30: =SUM(C30:N30) -> 256.8972
A31: Total payment retries | B31: EUR | C31: =C28+C30 -> 0 | D31: =D28+D30 -> 0 | E31: =E28+E30 -> 0 | F31: =F28+F30 -> 0 | G31: =G28+G30 -> 0 | H31: =H28+H30 -> 0 | I31: =I28+I30 -> 120.72582 | J31: =J28+J30 -> 181.08873 | ... N31: =N28+N30 -> 423.26545 | O31: =SUM(C31:N31) -> 1630.5237
A33: Customer communications
A34: Invoices issued | B34: invoices | C34: =C9*Inputs!$C$40 -> 0 | D34: =D9*Inputs!$C$40 -> 0 | E34: =E9*Inputs!$C$40 -> 0 | F34: =F9*Inputs!$C$40 -> 0 | G34: =G9*Inputs!$C$40 -> 0 | H34: =H9*Inputs!$C$40 -> 0 | I34: =I9*Inputs!$C$40 -> 333 | J34: =J9*Inputs!$C$40 -> 666 | ... N34: =N9*Inputs!$C$40 -> 2000 | O34: =SUM(C34:N34) -> 6995
A35: Paper invoices | B35: invoices | C35: =C34*Inputs!$C$41 -> 0 | D35: =D34*Inputs!$C$41 -> 0 | E35: =E34*Inputs!$C$41 -> 0 | F35: =F34*Inputs!$C$41 -> 0 | G35: =G34*Inputs!$C$41 -> 0 | H35: =H34*Inputs!$C$41 -> 0 | I35: =I34*Inputs!$C$41 -> 66.6 | J35: =J34*Inputs!$C$41 -> 133.2 | ... N35: =N34*Inputs!$C$41 -> 400 | O35: =SUM(C35:N35) -> 1399
A36: Paper invoices - printing & enveloping | B36: EUR | C36: =C35*Inputs!$C$42 -> 0 | D36: =D35*Inputs!$C$42 -> 0 | E36: =E35*Inputs!$C$42 -> 0 | F36: =F35*Inputs!$C$42 -> 0 | G36: =G35*Inputs!$C$42 -> 0 | H36: =H35*Inputs!$C$42 -> 0 | I36: =I35*Inputs!$C$42 -> 33.3 | J36: =J35*Inputs!$C$42 -> 66.6 | ... N36: =N35*Inputs!$C$42 -> 200 | O36: =SUM(C36:N36) -> 699.5
A37: Paper invoices - postage | B37: EUR | C37: =C35*Inputs!$C$43 -> 0 | D37: =D35*Inputs!$C$43 -> 0 | E37: =E35*Inputs!$C$43 -> 0 | F37: =F35*Inputs!$C$43 -> 0 | G37: =G35*Inputs!$C$43 -> 0 | H37: =H35*Inputs!$C$43 -> 0 | I37: =I35*Inputs!$C$43 -> 66.6 | J37: =J35*Inputs!$C$43 -> 133.2 | ... N37: =N35*Inputs!$C$43 -> 400 | O37: =SUM(C37:N37) -> 1399
A38: SMS sent | B38: SMS | C38: =C9*Inputs!$C$44 -> 0 | D38: =D9*Inputs!$C$44 -> 0 | E38: =E9*Inputs!$C$44 -> 0 | F38: =F9*Inputs!$C$44 -> 0 | G38: =G9*Inputs!$C$44 -> 0 | H38: =H9*Inputs!$C$44 -> 0 | I38: =I9*Inputs!$C$44 -> 0 | J38: =J9*Inputs!$C$44 -> 0 | ... N38: =N9*Inputs!$C$44 -> 0 | O38: =SUM(C38:N38) -> 0
A39: SMS | B39: EUR | C39: =C38*Inputs!$C$45 -> 0 | D39: =D38*Inputs!$C$45 -> 0 | E39: =E38*Inputs!$C$45 -> 0 | F39: =F38*Inputs!$C$45 -> 0 | G39: =G38*Inputs!$C$45 -> 0 | H39: =H38*Inputs!$C$45 -> 0 | I39: =I38*Inputs!$C$45 -> 0 | J39: =J38*Inputs!$C$45 -> 0 | ... N39: =N38*Inputs!$C$45 -> 0 | O39: =SUM(C39:N39) -> 0
A41: Customer service
A42: Inbound calls | B42: calls | C42: =C9*Inputs!$C$48 -> 0 | D42: =D9*Inputs!$C$48 -> 0 | E42: =E9*Inputs!$C$48 -> 0 | F42: =F9*Inputs!$C$48 -> 0 | G42: =G9*Inputs!$C$48 -> 0 | H42: =H9*Inputs!$C$48 -> 0 | I42: =I9*Inputs!$C$48 -> 999 | J42: =J9*Inputs!$C$48 -> 1998 | ... N42: =N9*Inputs!$C$48 -> 6000 | O42: =SUM(C42:N42) -> 20985
A43: Path 1 - AI calls | B43: calls | C43: =C42*Inputs!$C$49 -> 0 | D43: =D42*Inputs!$C$49 -> 0 | E43: =E42*Inputs!$C$49 -> 0 | F43: =F42*Inputs!$C$49 -> 0 | G43: =G42*Inputs!$C$49 -> 0 | H43: =H42*Inputs!$C$49 -> 0 | I43: =I42*Inputs!$C$49 -> 599.4 | J43: =J42*Inputs!$C$49 -> 1198.8 | ... N43: =N42*Inputs!$C$49 -> 3600 | O43: =SUM(C43:N43) -> 12591
A44: Path 2 - calls routed directly to a human | B44: calls | C44: =C42*Inputs!$C$50 -> 0 | D44: =D42*Inputs!$C$50 -> 0 | E44: =E42*Inputs!$C$50 -> 0 | F44: =F42*Inputs!$C$50 -> 0 | G44: =G42*Inputs!$C$50 -> 0 | H44: =H42*Inputs!$C$50 -> 0 | I44: =I42*Inputs!$C$50 -> 199.8 | J44: =J42*Inputs!$C$50 -> 399.6 | ... N44: =N42*Inputs!$C$50 -> 1200 | O44: =SUM(C44:N44) -> 4197
A45: Path 3 - calls with no human and no AI | B45: calls | C45: =C42*Inputs!$C$51 -> 0 | D45: =D42*Inputs!$C$51 -> 0 | E45: =E42*Inputs!$C$51 -> 0 | F45: =F42*Inputs!$C$51 -> 0 | G45: =G42*Inputs!$C$51 -> 0 | H45: =H42*Inputs!$C$51 -> 0 | I45: =I42*Inputs!$C$51 -> 199.8 | J45: =J42*Inputs!$C$51 -> 399.6 | ... N45: =N42*Inputs!$C$51 -> 1200 | O45: =SUM(C45:N45) -> 4197
A46: AI calls escalated to a human | B46: calls | C46: =C43*Inputs!$C$53 -> 0 | D46: =D43*Inputs!$C$53 -> 0 | E46: =E43*Inputs!$C$53 -> 0 | F46: =F43*Inputs!$C$53 -> 0 | G46: =G43*Inputs!$C$53 -> 0 | H46: =H43*Inputs!$C$53 -> 0 | I46: =I43*Inputs!$C$53 -> 179.82 | J46: =J43*Inputs!$C$53 -> 359.64 | ... N46: =N43*Inputs!$C$53 -> 1080 | O46: =SUM(C46:N46) -> 3777.3
A47: Total calls handled by a human | B47: calls | C47: =C44+C46 -> 0 | D47: =D44+D46 -> 0 | E47: =E44+E46 -> 0 | F47: =F44+F46 -> 0 | G47: =G44+G46 -> 0 | H47: =H44+H46 -> 0 | I47: =I44+I46 -> 379.62 | J47: =J44+J46 -> 759.24 | ... N47: =N44+N46 -> 2280 | O47: =SUM(C47:N47) -> 7974.3
...

Sheet Personnel
A1: Personnel - one row per person or role
A2: Enter ID, role, department, dates, FTE, quarterly cost (from the HR analysis, at 1 FTE) and hiring fee. Monthly FTE pro-rated by calendar days. Blank end date = open.
I4: Month start | J4: 46388 | K4: 46419 | L4: 46447 | M4: 46478 | N4: 46508 | O4: 46539 | P4: 46569 | Q4: 46600 | R4: 46631 | S4: 46661 | T4: 46692 | U4: 46722 | V4: 46388 | W4: 46419 | X4: 46447 | Y4: 46478 | Z4: 46508 | AA4: 46539 | AB4: 46569 | AC4: 46600 | AD4: 46631 | AE4: 46661 | AF4: 46692 | AG4: 46722
I5: Month end | J5: 46418 | K5: 46446 | L5: 46477 | M5: 46507 | N5: 46538 | O5: 46568 | P5: 46599 | Q5: 46630 | R5: 46660 | S5: 46691 | T5: 46721 | U5: 46752 | V5: 46418 | W5: 46446 | X5: 46477 | Y5: 46507 | Z5: 46538 | AA5: 46568 | AB5: 46599 | AC5: 46630 | AD5: 46660 | AE5: 46691 | AF5: 46721 | AG5: 46752
J6: Monthly FTE | V6: Monthly cost (EUR)
A7: ID | B7: Role | C7: Department | D7: Description / assumption | E7: Start | F7: End (blank = open) | G7: FTE | H7: Quarterly cost at 1 FTE (EUR) | I7: One-off hiring fee (EUR) | J7: FTE Jan-27 | K7: FTE Feb-27 | L7: FTE Mar-27 | M7: FTE Apr-27 | N7: FTE May-27 | O7: FTE Jun-27 | P7: FTE Jul-27 | Q7: FTE Aug-27 | R7: FTE Sep-27 | S7: FTE Oct-27 | T7: FTE Nov-27 | U7: FTE Dec-27 | V7: Cost Jan-27 | W7: Cost Feb-27 | X7: Cost Mar-27 | Y7: Cost Apr-27 | Z7: Cost May-27 | AA7: Cost Jun-27 | AB7: Cost Jul-27 | AC7: Cost Aug-27 | AD7: Cost Sep-27 | AE7: Cost Oct-27 | AF7: Cost Nov-27 | AG7: Cost Dec-27 | AH7: Total 2027 (EUR)
A8: R01 | B8: Chief Operating Officer | C8: Operations & Service | D8: Switzerland · cross-country · Product Manager & Excellence Lead. Covering Credit risk Management | E8: 46296 | G8: 1 | H8: 58500 | I8: 0 | J8: =IF($E8="",0,$G8*MAX(0,MIN(J$5,IF($F8="",J$5,$F8))-MAX(J$4,$E8)+1)/(J$5-J$4+1)) -> 1 | K8: =IF($E8="",0,$G8*MAX(0,MIN(K$5,IF($F8="",K$5,$F8))-MAX(K$4,$E8)+1)/(K$5-K$4+1)) -> 1 | L8: =IF($E8="",0,$G8*MAX(0,MIN(L$5,IF($F8="",L$5,$F8))-MAX(L$4,$E8)+1)/(L$5-L$4+1)) -> 1 | M8: =IF($E8="",0,$G8*MAX(0,MIN(M$5,IF($F8="",M$5,$F8))-MAX(M$4,$E8)+1)/(M$5-M$4+1)) -> 1 | N8: =IF($E8="",0,$G8*MAX(0,MIN(N$5,IF($F8="",N$5,$F8))-MAX(N$4,$E8)+1)/(N$5-N$4+1)) -> 1 | O8: =IF($E8="",0,$G8*MAX(0,MIN(O$5,IF($F8="",O$5,$F8))-MAX(O$4,$E8)+1)/(O$5-O$4+1)) -> 1 | P8: =IF($E8="",0,$G8*MAX(0,MIN(P$5,IF($F8="",P$5,$F8))-MAX(P$4,$E8)+1)/(P$5-P$4+1)) -> 1 | Q8: =IF($E8="",0,$G8*MAX(0,MIN(Q$5,IF($F8="",Q$5,$F8))-MAX(Q$4,$E8)+1)/(Q$5-Q$4+1)) -> 1 | ... U8: =IF($E8="",0,$G8*MAX(0,MIN(U$5,IF($F8="",U$5,$F8))-MAX(U$4,$E8)+1)/(U$5-U$4+1)) -> 1 | V8: =$H8/3*J8+IF(AND($E8<>"",$E8>=V$4,$E8<=V$5),$I8,0) -> 19500 | W8: =$H8/3*K8+IF(AND($E8<>"",$E8>=W$4,$E8<=W$5),$I8,0) -> 19500 | X8: =$H8/3*L8+IF(AND($E8<>"",$E8>=X$4,$E8<=X$5),$I8,0) -> 19500 | Y8: =$H8/3*M8+IF(AND($E8<>"",$E8>=Y$4,$E8<=Y$5),$I8,0) -> 19500 | Z8: =$H8/3*N8+IF(AND($E8<>"",$E8>=Z$4,$E8<=Z$5),$I8,0) -> 19500 | AA8: =$H8/3*O8+IF(AND($E8<>"",$E8>=AA$4,$E8<=AA$5),$I8,0) -> 19500 | AB8: =$H8/3*P8+IF(AND($E8<>"",$E8>=AB$4,$E8<=AB$5),$I8,0) -> 19500 | AC8: =$H8/3*Q8+IF(AND($E8<>"",$E8>=AC$4,$E8<=AC$5),$I8,0) -> 19500 | ... AG8: =$H8/3*U8+IF(AND($E8<>"",$E8>=AG$4,$E8<=AG$5),$I8,0) -> 19500 | AH8: =SUM(V8:AG8) -> 234000
A9: R02 | B9: Deputy COO & Innovation Lead | C9: Operations & Service | D9: Spain · cross-country · Co Product Manager covering AI innovation | E9: 46388 | G9: 1 | H9: 50250 | I9: 0 | J9: =IF($E9="",0,$G9*MAX(0,MIN(J$5,IF($F9="",J$5,$F9))-MAX(J$4,$E9)+1)/(J$5-J$4+1)) -> 1 | K9: =IF($E9="",0,$G9*MAX(0,MIN(K$5,IF($F9="",K$5,$F9))-MAX(K$4,$E9)+1)/(K$5-K$4+1)) -> 1 | L9: =IF($E9="",0,$G9*MAX(0,MIN(L$5,IF($F9="",L$5,$F9))-MAX(L$4,$E9)+1)/(L$5-L$4+1)) -> 1 | M9: =IF($E9="",0,$G9*MAX(0,MIN(M$5,IF($F9="",M$5,$F9))-MAX(M$4,$E9)+1)/(M$5-M$4+1)) -> 1 | N9: =IF($E9="",0,$G9*MAX(0,MIN(N$5,IF($F9="",N$5,$F9))-MAX(N$4,$E9)+1)/(N$5-N$4+1)) -> 1 | O9: =IF($E9="",0,$G9*MAX(0,MIN(O$5,IF($F9="",O$5,$F9))-MAX(O$4,$E9)+1)/(O$5-O$4+1)) -> 1 | P9: =IF($E9="",0,$G9*MAX(0,MIN(P$5,IF($F9="",P$5,$F9))-MAX(P$4,$E9)+1)/(P$5-P$4+1)) -> 1 | Q9: =IF($E9="",0,$G9*MAX(0,MIN(Q$5,IF($F9="",Q$5,$F9))-MAX(Q$4,$E9)+1)/(Q$5-Q$4+1)) -> 1 | ... U9: =IF($E9="",0,$G9*MAX(0,MIN(U$5,IF($F9="",U$5,$F9))-MAX(U$4,$E9)+1)/(U$5-U$4+1)) -> 1 | V9: =$H9/3*J9+IF(AND($E9<>"",$E9>=V$4,$E9<=V$5),$I9,0) -> 16750 | W9: =$H9/3*K9+IF(AND($E9<>"",$E9>=W$4,$E9<=W$5),$I9,0) -> 16750 | X9: =$H9/3*L9+IF(AND($E9<>"",$E9>=X$4,$E9<=X$5),$I9,0) -> 16750 | Y9: =$H9/3*M9+IF(AND($E9<>"",$E9>=Y$4,$E9<=Y$5),$I9,0) -> 16750 | Z9: =$H9/3*N9+IF(AND($E9<>"",$E9>=Z$4,$E9<=Z$5),$I9,0) -> 16750 | AA9: =$H9/3*O9+IF(AND($E9<>"",$E9>=AA$4,$E9<=AA$5),$I9,0) -> 16750 | AB9: =$H9/3*P9+IF(AND($E9<>"",$E9>=AB$4,$E9<=AB$5),$I9,0) -> 16750 | AC9: =$H9/3*Q9+IF(AND($E9<>"",$E9>=AC$4,$E9<=AC$5),$I9,0) -> 16750 | ... AG9: =$H9/3*U9+IF(AND($E9<>"",$E9>=AG$4,$E9<=AG$5),$I9,0) -> 16750 | AH9: =SUM(V9:AG9) -> 201000
A10: R03 | B10: Customer Excellence Manager | C10: Customer Service | D10: Spain · cross-country · Optimization Team / Direct Report to COO · hired via agency (20% of salary) | E10: 46478 | G10: 1 | H10: 16750 | I10: 10000 | J10: =IF($E10="",0,$G10*MAX(0,MIN(J$5,IF($F10="",J$5,$F10))-MAX(J$4,$E10)+1)/(J$5-J$4+1)) -> 0 | K10: =IF($E10="",0,$G10*MAX(0,MIN(K$5,IF($F10="",K$5,$F10))-MAX(K$4,$E10)+1)/(K$5-K$4+1)) -> 0 | L10: =IF($E10="",0,$G10*MAX(0,MIN(L$5,IF($F10="",L$5,$F10))-MAX(L$4,$E10)+1)/(L$5-L$4+1)) -> 0 | M10: =IF($E10="",0,$G10*MAX(0,MIN(M$5,IF($F10="",M$5,$F10))-MAX(M$4,$E10)+1)/(M$5-M$4+1)) -> 1 | N10: =IF($E10="",0,$G10*MAX(0,MIN(N$5,IF($F10="",N$5,$F10))-MAX(N$4,$E10)+1)/(N$5-N$4+1)) -> 1 | O10: =IF($E10="",0,$G10*MAX(0,MIN(O$5,IF($F10="",O$5,$F10))-MAX(O$4,$E10)+1)/(O$5-O$4+1)) -> 1 | P10: =IF($E10="",0,$G10*MAX(0,MIN(P$5,IF($F10="",P$5,$F10))-MAX(P$4,$E10)+1)/(P$5-P$4+1)) -> 1 | Q10: =IF($E10="",0,$G10*MAX(0,MIN(Q$5,IF($F10="",Q$5,$F10))-MAX(Q$4,$E10)+1)/(Q$5-Q$4+1)) -> 1 | ... U10: =IF($E10="",0,$G10*MAX(0,MIN(U$5,IF($F10="",U$5,$F10))-MAX(U$4,$E10)+1)/(U$5-U$4+1)) -> 1 | V10: =$H10/3*J10+IF(AND($E10<>"",$E10>=V$4,$E10<=V$5),$I10,0) -> 0 | W10: =$H10/3*K10+IF(AND($E10<>"",$E10>=W$4,$E10<=W$5),$I10,0) -> 0 | X10: =$H10/3*L10+IF(AND($E10<>"",$E10>=X$4,$E10<=X$5),$I10,0) -> 0 | Y10: =$H10/3*M10+IF(AND($E10<>"",$E10>=Y$4,$E10<=Y$5),$I10,0) -> 15583.333 | Z10: =$H10/3*N10+IF(AND($E10<>"",$E10>=Z$4,$E10<=Z$5),$I10,0) -> 5583.3333 | AA10: =$H10/3*O10+IF(AND($E10<>"",$E10>=AA$4,$E10<=AA$5),$I10,0) -> 5583.3333 | AB10: =$H10/3*P10+IF(AND($E10<>"",$E10>=AB$4,$E10<=AB$5),$I10,0) -> 5583.3333 | AC10: =$H10/3*Q10+IF(AND($E10<>"",$E10>=AC$4,$E10<=AC$5),$I10,0) -> 5583.3333 | ... AG10: =$H10/3*U10+IF(AND($E10<>"",$E10>=AG$4,$E10<=AG$5),$I10,0) -> 5583.3333 | AH10: =SUM(V10:AG10) -> 60250
A11: R04 | B11: Customer Service Manager | C11: Customer Service | D11: Spain · cross-country · Core Team & Team Lead / Direct Report to COO | E11: 46296 | G11: 1 | H11: 12730 | I11: 0 | J11: =IF($E11="",0,$G11*MAX(0,MIN(J$5,IF($F11="",J$5,$F11))-MAX(J$4,$E11)+1)/(J$5-J$4+1)) -> 1 | K11: =IF($E11="",0,$G11*MAX(0,MIN(K$5,IF($F11="",K$5,$F11))-MAX(K$4,$E11)+1)/(K$5-K$4+1)) -> 1 | L11: =IF($E11="",0,$G11*MAX(0,MIN(L$5,IF($F11="",L$5,$F11))-MAX(L$4,$E11)+1)/(L$5-L$4+1)) -> 1 | M11: =IF($E11="",0,$G11*MAX(0,MIN(M$5,IF($F11="",M$5,$F11))-MAX(M$4,$E11)+1)/(M$5-M$4+1)) -> 1 | N11: =IF($E11="",0,$G11*MAX(0,MIN(N$5,IF($F11="",N$5,$F11))-MAX(N$4,$E11)+1)/(N$5-N$4+1)) -> 1 | O11: =IF($E11="",0,$G11*MAX(0,MIN(O$5,IF($F11="",O$5,$F11))-MAX(O$4,$E11)+1)/(O$5-O$4+1)) -> 1 | P11: =IF($E11="",0,$G11*MAX(0,MIN(P$5,IF($F11="",P$5,$F11))-MAX(P$4,$E11)+1)/(P$5-P$4+1)) -> 1 | Q11: =IF($E11="",0,$G11*MAX(0,MIN(Q$5,IF($F11="",Q$5,$F11))-MAX(Q$4,$E11)+1)/(Q$5-Q$4+1)) -> 1 | ... U11: =IF($E11="",0,$G11*MAX(0,MIN(U$5,IF($F11="",U$5,$F11))-MAX(U$4,$E11)+1)/(U$5-U$4+1)) -> 1 | V11: =$H11/3*J11+IF(AND($E11<>"",$E11>=V$4,$E11<=V$5),$I11,0) -> 4243.3333 | W11: =$H11/3*K11+IF(AND($E11<>"",$E11>=W$4,$E11<=W$5),$I11,0) -> 4243.3333 | X11: =$H11/3*L11+IF(AND($E11<>"",$E11>=X$4,$E11<=X$5),$I11,0) -> 4243.3333 | Y11: =$H11/3*M11+IF(AND($E11<>"",$E11>=Y$4,$E11<=Y$5),$I11,0) -> 4243.3333 | Z11: =$H11/3*N11+IF(AND($E11<>"",$E11>=Z$4,$E11<=Z$5),$I11,0) -> 4243.3333 | AA11: =$H11/3*O11+IF(AND($E11<>"",$E11>=AA$4,$E11<=AA$5),$I11,0) -> 4243.3333 | AB11: =$H11/3*P11+IF(AND($E11<>"",$E11>=AB$4,$E11<=AB$5),$I11,0) -> 4243.3333 | AC11: =$H11/3*Q11+IF(AND($E11<>"",$E11>=AC$4,$E11<=AC$5),$I11,0) -> 4243.3333 | ... AG11: =$H11/3*U11+IF(AND($E11<>"",$E11>=AG$4,$E11<=AG$5),$I11,0) -> 4243.3333 | AH11: =SUM(V11:AG11) -> 50920
A12: R05 | B12: Customer Service Expert | C12: Customer Service | D12: Spain · country-specific · Core team | E12: 46478 | G12: 1 | H12: 8375 | I12: 0 | J12: =IF($E12="",0,$G12*MAX(0,MIN(J$5,IF($F12="",J$5,$F12))-MAX(J$4,$E12)+1)/(J$5-J$4+1)) -> 0 | K12: =IF($E12="",0,$G12*MAX(0,MIN(K$5,IF($F12="",K$5,$F12))-MAX(K$4,$E12)+1)/(K$5-K$4+1)) -> 0 | L12: =IF($E12="",0,$G12*MAX(0,MIN(L$5,IF($F12="",L$5,$F12))-MAX(L$4,$E12)+1)/(L$5-L$4+1)) -> 0 | M12: =IF($E12="",0,$G12*MAX(0,MIN(M$5,IF($F12="",M$5,$F12))-MAX(M$4,$E12)+1)/(M$5-M$4+1)) -> 1 | N12: =IF($E12="",0,$G12*MAX(0,MIN(N$5,IF($F12="",N$5,$F12))-MAX(N$4,$E12)+1)/(N$5-N$4+1)) -> 1 | O12: =IF($E12="",0,$G12*MAX(0,MIN(O$5,IF($F12="",O$5,$F12))-MAX(O$4,$E12)+1)/(O$5-O$4+1)) -> 1 | P12: =IF($E12="",0,$G12*MAX(0,MIN(P$5,IF($F12="",P$5,$F12))-MAX(P$4,$E12)+1)/(P$5-P$4+1)) -> 1 | Q12: =IF($E12="",0,$G12*MAX(0,MIN(Q$5,IF($F12="",Q$5,$F12))-MAX(Q$4,$E12)+1)/(Q$5-Q$4+1)) -> 1 | ... U12: =IF($E12="",0,$G12*MAX(0,MIN(U$5,IF($F12="",U$5,$F12))-MAX(U$4,$E12)+1)/(U$5-U$4+1)) -> 1 | V12: =$H12/3*J12+IF(AND($E12<>"",$E12>=V$4,$E12<=V$5),$I12,0) -> 0 | W12: =$H12/3*K12+IF(AND($E12<>"",$E12>=W$4,$E12<=W$5),$I12,0) -> 0 | X12: =$H12/3*L12+IF(AND($E12<>"",$E12>=X$4,$E12<=X$5),$I12,0) -> 0 | Y12: =$H12/3*M12+IF(AND($E12<>"",$E12>=Y$4,$E12<=Y$5),$I12,0) -> 2791.6667 | Z12: =$H12/3*N12+IF(AND($E12<>"",$E12>=Z$4,$E12<=Z$5),$I12,0) -> 2791.6667 | AA12: =$H12/3*O12+IF(AND($E12<>"",$E12>=AA$4,$E12<=AA$5),$I12,0) -> 2791.6667 | AB12: =$H12/3*P12+IF(AND($E12<>"",$E12>=AB$4,$E12<=AB$5),$I12,0) -> 2791.6667 | AC12: =$H12/3*Q12+IF(AND($E12<>"",$E12>=AC$4,$E12<=AC$5),$I12,0) -> 2791.6667 | ... AG12: =$H12/3*U12+IF(AND($E12<>"",$E12>=AG$4,$E12<=AG$5),$I12,0) -> 2791.6667 | AH12: =SUM(V12:AG12) -> 25125
A13: R06 | B13: Cash Management Expert | C13: Billing & Invoicing | D13: Spain · cross-country · Core team / (potential little buffer) | E13: 46478 | G13: 1 | H13: 11725 | I13: 0 | J13: =IF($E13="",0,$G13*MAX(0,MIN(J$5,IF($F13="",J$5,$F13))-MAX(J$4,$E13)+1)/(J$5-J$4+1)) -> 0 | K13: =IF($E13="",0,$G13*MAX(0,MIN(K$5,IF($F13="",K$5,$F13))-MAX(K$4,$E13)+1)/(K$5-K$4+1)) -> 0 | L13: =IF($E13="",0,$G13*MAX(0,MIN(L$5,IF($F13="",L$5,$F13))-MAX(L$4,$E13)+1)/(L$5-L$4+1)) -> 0 | M13: =IF($E13="",0,$G13*MAX(0,MIN(M$5,IF($F13="",M$5,$F13))-MAX(M$4,$E13)+1)/(M$5-M$4+1)) -> 1 | N13: =IF($E13="",0,$G13*MAX(0,MIN(N$5,IF($F13="",N$5,$F13))-MAX(N$4,$E13)+1)/(N$5-N$4+1)) -> 1 | O13: =IF($E13="",0,$G13*MAX(0,MIN(O$5,IF($F13="",O$5,$F13))-MAX(O$4,$E13)+1)/(O$5-O$4+1)) -> 1 | P13: =IF($E13="",0,$G13*MAX(0,MIN(P$5,IF($F13="",P$5,$F13))-MAX(P$4,$E13)+1)/(P$5-P$4+1)) -> 1 | Q13: =IF($E13="",0,$G13*MAX(0,MIN(Q$5,IF($F13="",Q$5,$F13))-MAX(Q$4,$E13)+1)/(Q$5-Q$4+1)) -> 1 | ... U13: =IF($E13="",0,$G13*MAX(0,MIN(U$5,IF($F13="",U$5,$F13))-MAX(U$4,$E13)+1)/(U$5-U$4+1)) -> 1 | V13: =$H13/3*J13+IF(AND($E13<>"",$E13>=V$4,$E13<=V$5),$I13,0) -> 0 | W13: =$H13/3*K13+IF(AND($E13<>"",$E13>=W$4,$E13<=W$5),$I13,0) -> 0 | X13: =$H13/3*L13+IF(AND($E13<>"",$E13>=X$4,$E13<=X$5),$I13,0) -> 0 | Y13: =$H13/3*M13+IF(AND($E13<>"",$E13>=Y$4,$E13<=Y$5),$I13,0) -> 3908.3333 | Z13: =$H13/3*N13+IF(AND($E13<>"",$E13>=Z$4,$E13<=Z$5),$I13,0) -> 3908.3333 | AA13: =$H13/3*O13+IF(AND($E13<>"",$E13>=AA$4,$E13<=AA$5),$I13,0) -> 3908.3333 | AB13: =$H13/3*P13+IF(AND($E13<>"",$E13>=AB$4,$E13<=AB$5),$I13,0) -> 3908.3333 | AC13: =$H13/3*Q13+IF(AND($E13<>"",$E13>=AC$4,$E13<=AC$5),$I13,0) -> 3908.3333 | ... AG13: =$H13/3*U13+IF(AND($E13<>"",$E13>=AG$4,$E13<=AG$5),$I13,0) -> 3908.3333 | AH13: =SUM(V13:AG13) -> 35175
A14: R07 | B14: Switching & Metering Manager | C14: Switching & Metering | D14: Spain · cross-country · Core Team & Team Lead / Direct Report to COO · hired via agency (20% of salary) | E14: 46296 | G14: 1 | H14: 16750 | I14: 10000 | J14: =IF($E14="",0,$G14*MAX(0,MIN(J$5,IF($F14="",J$5,$F14))-MAX(J$4,$E14)+1)/(J$5-J$4+1)) -> 1 | K14: =IF($E14="",0,$G14*MAX(0,MIN(K$5,IF($F14="",K$5,$F14))-MAX(K$4,$E14)+1)/(K$5-K$4+1)) -> 1 | L14: =IF($E14="",0,$G14*MAX(0,MIN(L$5,IF($F14="",L$5,$F14))-MAX(L$4,$E14)+1)/(L$5-L$4+1)) -> 1 | M14: =IF($E14="",0,$G14*MAX(0,MIN(M$5,IF($F14="",M$5,$F14))-MAX(M$4,$E14)+1)/(M$5-M$4+1)) -> 1 | N14: =IF($E14="",0,$G14*MAX(0,MIN(N$5,IF($F14="",N$5,$F14))-MAX(N$4,$E14)+1)/(N$5-N$4+1)) -> 1 | O14: =IF($E14="",0,$G14*MAX(0,MIN(O$5,IF($F14="",O$5,$F14))-MAX(O$4,$E14)+1)/(O$5-O$4+1)) -> 1 | P14: =IF($E14="",0,$G14*MAX(0,MIN(P$5,IF($F14="",P$5,$F14))-MAX(P$4,$E14)+1)/(P$5-P$4+1)) -> 1 | Q14: =IF($E14="",0,$G14*MAX(0,MIN(Q$5,IF($F14="",Q$5,$F14))-MAX(Q$4,$E14)+1)/(Q$5-Q$4+1)) -> 1 | ... U14: =IF($E14="",0,$G14*MAX(0,MIN(U$5,IF($F14="",U$5,$F14))-MAX(U$4,$E14)+1)/(U$5-U$4+1)) -> 1 | V14: =$H14/3*J14+IF(AND($E14<>"",$E14>=V$4,$E14<=V$5),$I14,0) -> 5583.3333 | W14: =$H14/3*K14+IF(AND($E14<>"",$E14>=W$4,$E14<=W$5),$I14,0) -> 5583.3333 | X14: =$H14/3*L14+IF(AND($E14<>"",$E14>=X$4,$E14<=X$5),$I14,0) -> 5583.3333 | Y14: =$H14/3*M14+IF(AND($E14<>"",$E14>=Y$4,$E14<=Y$5),$I14,0) -> 5583.3333 | Z14: =$H14/3*N14+IF(AND($E14<>"",$E14>=Z$4,$E14<=Z$5),$I14,0) -> 5583.3333 | AA14: =$H14/3*O14+IF(AND($E14<>"",$E14>=AA$4,$E14<=AA$5),$I14,0) -> 5583.3333 | AB14: =$H14/3*P14+IF(AND($E14<>"",$E14>=AB$4,$E14<=AB$5),$I14,0) -> 5583.3333 | AC14: =$H14/3*Q14+IF(AND($E14<>"",$E14>=AC$4,$E14<=AC$5),$I14,0) -> 5583.3333 | ... AG14: =$H14/3*U14+IF(AND($E14<>"",$E14>=AG$4,$E14<=AG$5),$I14,0) -> 5583.3333 | AH14: =SUM(V14:AG14) -> 67000
A15: R08 | B15: Switching & Metering Expert | C15: Switching & Metering | D15: Spain · country-specific · Core Team | E15: 46388 | G15: 1 | H15: 12060 | I15: 0 | J15: =IF($E15="",0,$G15*MAX(0,MIN(J$5,IF($F15="",J$5,$F15))-MAX(J$4,$E15)+1)/(J$5-J$4+1)) -> 1 | K15: =IF($E15="",0,$G15*MAX(0,MIN(K$5,IF($F15="",K$5,$F15))-MAX(K$4,$E15)+1)/(K$5-K$4+1)) -> 1 | L15: =IF($E15="",0,$G15*MAX(0,MIN(L$5,IF($F15="",L$5,$F15))-MAX(L$4,$E15)+1)/(L$5-L$4+1)) -> 1 | M15: =IF($E15="",0,$G15*MAX(0,MIN(M$5,IF($F15="",M$5,$F15))-MAX(M$4,$E15)+1)/(M$5-M$4+1)) -> 1 | N15: =IF($E15="",0,$G15*MAX(0,MIN(N$5,IF($F15="",N$5,$F15))-MAX(N$4,$E15)+1)/(N$5-N$4+1)) -> 1 | O15: =IF($E15="",0,$G15*MAX(0,MIN(O$5,IF($F15="",O$5,$F15))-MAX(O$4,$E15)+1)/(O$5-O$4+1)) -> 1 | P15: =IF($E15="",0,$G15*MAX(0,MIN(P$5,IF($F15="",P$5,$F15))-MAX(P$4,$E15)+1)/(P$5-P$4+1)) -> 1 | Q15: =IF($E15="",0,$G15*MAX(0,MIN(Q$5,IF($F15="",Q$5,$F15))-MAX(Q$4,$E15)+1)/(Q$5-Q$4+1)) -> 1 | ... U15: =IF($E15="",0,$G15*MAX(0,MIN(U$5,IF($F15="",U$5,$F15))-MAX(U$4,$E15)+1)/(U$5-U$4+1)) -> 1 | V15: =$H15/3*J15+IF(AND($E15<>"",$E15>=V$4,$E15<=V$5),$I15,0) -> 4020 | W15: =$H15/3*K15+IF(AND($E15<>"",$E15>=W$4,$E15<=W$5),$I15,0) -> 4020 | X15: =$H15/3*L15+IF(AND($E15<>"",$E15>=X$4,$E15<=X$5),$I15,0) -> 4020 | Y15: =$H15/3*M15+IF(AND($E15<>"",$E15>=Y$4,$E15<=Y$5),$I15,0) -> 4020 | Z15: =$H15/3*N15+IF(AND($E15<>"",$E15>=Z$4,$E15<=Z$5),$I15,0) -> 4020 | AA15: =$H15/3*O15+IF(AND($E15<>"",$E15>=AA$4,$E15<=AA$5),$I15,0) -> 4020 | AB15: =$H15/3*P15+IF(AND($E15<>"",$E15>=AB$4,$E15<=AB$5),$I15,0) -> 4020 | AC15: =$H15/3*Q15+IF(AND($E15<>"",$E15>=AC$4,$E15<=AC$5),$I15,0) -> 4020 | ... AG15: =$H15/3*U15+IF(AND($E15<>"",$E15>=AG$4,$E15<=AG$5),$I15,0) -> 4020 | AH15: =SUM(V15:AG15) -> 48240
A16: R09 | B16: Pricing & Forecasting Expert | C16: Pricing & Risk Management | D16: Spain · country-specific · Core Team & Team Lead / Direct Report to COO | E16: 46296 | G16: 1 | H16: 19430 | I16: 0 | J16: =IF($E16="",0,$G16*MAX(0,MIN(J$5,IF($F16="",J$5,$F16))-MAX(J$4,$E16)+1)/(J$5-J$4+1)) -> 1 | K16: =IF($E16="",0,$G16*MAX(0,MIN(K$5,IF($F16="",K$5,$F16))-MAX(K$4,$E16)+1)/(K$5-K$4+1)) -> 1 | L16: =IF($E16="",0,$G16*MAX(0,MIN(L$5,IF($F16="",L$5,$F16))-MAX(L$4,$E16)+1)/(L$5-L$4+1)) -> 1 | M16: =IF($E16="",0,$G16*MAX(0,MIN(M$5,IF($F16="",M$5,$F16))-MAX(M$4,$E16)+1)/(M$5-M$4+1)) -> 1 | N16: =IF($E16="",0,$G16*MAX(0,MIN(N$5,IF($F16="",N$5,$F16))-MAX(N$4,$E16)+1)/(N$5-N$4+1)) -> 1 | O16: =IF($E16="",0,$G16*MAX(0,MIN(O$5,IF($F16="",O$5,$F16))-MAX(O$4,$E16)+1)/(O$5-O$4+1)) -> 1 | P16: =IF($E16="",0,$G16*MAX(0,MIN(P$5,IF($F16="",P$5,$F16))-MAX(P$4,$E16)+1)/(P$5-P$4+1)) -> 1 | Q16: =IF($E16="",0,$G16*MAX(0,MIN(Q$5,IF($F16="",Q$5,$F16))-MAX(Q$4,$E16)+1)/(Q$5-Q$4+1)) -> 1 | ... U16: =IF($E16="",0,$G16*MAX(0,MIN(U$5,IF($F16="",U$5,$F16))-MAX(U$4,$E16)+1)/(U$5-U$4+1)) -> 1 | V16: =$H16/3*J16+IF(AND($E16<>"",$E16>=V$4,$E16<=V$5),$I16,0) -> 6476.6667 | W16: =$H16/3*K16+IF(AND($E16<>"",$E16>=W$4,$E16<=W$5),$I16,0) -> 6476.6667 | X16: =$H16/3*L16+IF(AND($E16<>"",$E16>=X$4,$E16<=X$5),$I16,0) -> 6476.6667 | Y16: =$H16/3*M16+IF(AND($E16<>"",$E16>=Y$4,$E16<=Y$5),$I16,0) -> 6476.6667 | Z16: =$H16/3*N16+IF(AND($E16<>"",$E16>=Z$4,$E16<=Z$5),$I16,0) -> 6476.6667 | AA16: =$H16/3*O16+IF(AND($E16<>"",$E16>=AA$4,$E16<=AA$5),$I16,0) -> 6476.6667 | AB16: =$H16/3*P16+IF(AND($E16<>"",$E16>=AB$4,$E16<=AB$5),$I16,0) -> 6476.6667 | AC16: =$H16/3*Q16+IF(AND($E16<>"",$E16>=AC$4,$E16<=AC$5),$I16,0) -> 6476.6667 | ... AG16: =$H16/3*U16+IF(AND($E16<>"",$E16>=AG$4,$E16<=AG$5),$I16,0) -> 6476.6667 | AH16: =SUM(V16:AG16) -> 77720
A17: R10 | B17: Quant Analyst & Market Risk | C17: Pricing & Risk Management | D17: Spain · cross-country · Optimization Team | E17: 46478 | G17: 1 | H17: 16750 | I17: 0 | J17: =IF($E17="",0,$G17*MAX(0,MIN(J$5,IF($F17="",J$5,$F17))-MAX(J$4,$E17)+1)/(J$5-J$4+1)) -> 0 | K17: =IF($E17="",0,$G17*MAX(0,MIN(K$5,IF($F17="",K$5,$F17))-MAX(K$4,$E17)+1)/(K$5-K$4+1)) -> 0 | L17: =IF($E17="",0,$G17*MAX(0,MIN(L$5,IF($F17="",L$5,$F17))-MAX(L$4,$E17)+1)/(L$5-L$4+1)) -> 0 | M17: =IF($E17="",0,$G17*MAX(0,MIN(M$5,IF($F17="",M$5,$F17))-MAX(M$4,$E17)+1)/(M$5-M$4+1)) -> 1 | N17: =IF($E17="",0,$G17*MAX(0,MIN(N$5,IF($F17="",N$5,$F17))-MAX(N$4,$E17)+1)/(N$5-N$4+1)) -> 1 | O17: =IF($E17="",0,$G17*MAX(0,MIN(O$5,IF($F17="",O$5,$F17))-MAX(O$4,$E17)+1)/(O$5-O$4+1)) -> 1 | P17: =IF($E17="",0,$G17*MAX(0,MIN(P$5,IF($F17="",P$5,$F17))-MAX(P$4,$E17)+1)/(P$5-P$4+1)) -> 1 | Q17: =IF($E17="",0,$G17*MAX(0,MIN(Q$5,IF($F17="",Q$5,$F17))-MAX(Q$4,$E17)+1)/(Q$5-Q$4+1)) -> 1 | ... U17: =IF($E17="",0,$G17*MAX(0,MIN(U$5,IF($F17="",U$5,$F17))-MAX(U$4,$E17)+1)/(U$5-U$4+1)) -> 1 | V17: =$H17/3*J17+IF(AND($E17<>"",$E17>=V$4,$E17<=V$5),$I17,0) -> 0 | W17: =$H17/3*K17+IF(AND($E17<>"",$E17>=W$4,$E17<=W$5),$I17,0) -> 0 | X17: =$H17/3*L17+IF(AND($E17<>"",$E17>=X$4,$E17<=X$5),$I17,0) -> 0 | Y17: =$H17/3*M17+IF(AND($E17<>"",$E17>=Y$4,$E17<=Y$5),$I17,0) -> 5583.3333 | Z17: =$H17/3*N17+IF(AND($E17<>"",$E17>=Z$4,$E17<=Z$5),$I17,0) -> 5583.3333 | AA17: =$H17/3*O17+IF(AND($E17<>"",$E17>=AA$4,$E17<=AA$5),$I17,0) -> 5583.3333 | AB17: =$H17/3*P17+IF(AND($E17<>"",$E17>=AB$4,$E17<=AB$5),$I17,0) -> 5583.3333 | AC17: =$H17/3*Q17+IF(AND($E17<>"",$E17>=AC$4,$E17<=AC$5),$I17,0) -> 5583.3333 | ... AG17: =$H17/3*U17+IF(AND($E17<>"",$E17>=AG$4,$E17<=AG$5),$I17,0) -> 5583.3333 | AH17: =SUM(V17:AG17) -> 50250
A18: R11 | B18: Billing & invoicing Manager | C18: Billing & Invoicing | D18: Spain · cross-country · Core Team & Team lead / Direct Report to COO · hired via agency (20% of salary) | E18: 46296 | G18: 1 | H18: 16750 | I18: 10000 | J18: =IF($E18="",0,$G18*MAX(0,MIN(J$5,IF($F18="",J$5,$F18))-MAX(J$4,$E18)+1)/(J$5-J$4+1)) -> 1 | K18: =IF($E18="",0,$G18*MAX(0,MIN(K$5,IF($F18="",K$5,$F18))-MAX(K$4,$E18)+1)/(K$5-K$4+1)) -> 1 | L18: =IF($E18="",0,$G18*MAX(0,MIN(L$5,IF($F18="",L$5,$F18))-MAX(L$4,$E18)+1)/(L$5-L$4+1)) -> 1 | M18: =IF($E18="",0,$G18*MAX(0,MIN(M$5,IF($F18="",M$5,$F18))-MAX(M$4,$E18)+1)/(M$5-M$4+1)) -> 1 | N18: =IF($E18="",0,$G18*MAX(0,MIN(N$5,IF($F18="",N$5,$F18))-MAX(N$4,$E18)+1)/(N$5-N$4+1)) -> 1 | O18: =IF($E18="",0,$G18*MAX(0,MIN(O$5,IF($F18="",O$5,$F18))-MAX(O$4,$E18)+1)/(O$5-O$4+1)) -> 1 | P18: =IF($E18="",0,$G18*MAX(0,MIN(P$5,IF($F18="",P$5,$F18))-MAX(P$4,$E18)+1)/(P$5-P$4+1)) -> 1 | Q18: =IF($E18="",0,$G18*MAX(0,MIN(Q$5,IF($F18="",Q$5,$F18))-MAX(Q$4,$E18)+1)/(Q$5-Q$4+1)) -> 1 | ... U18: =IF($E18="",0,$G18*MAX(0,MIN(U$5,IF($F18="",U$5,$F18))-MAX(U$4,$E18)+1)/(U$5-U$4+1)) -> 1 | V18: =$H18/3*J18+IF(AND($E18<>"",$E18>=V$4,$E18<=V$5),$I18,0) -> 5583.3333 | W18: =$H18/3*K18+IF(AND($E18<>"",$E18>=W$4,$E18<=W$5),$I18,0) -> 5583.3333 | X18: =$H18/3*L18+IF(AND($E18<>"",$E18>=X$4,$E18<=X$5),$I18,0) -> 5583.3333 | Y18: =$H18/3*M18+IF(AND($E18<>"",$E18>=Y$4,$E18<=Y$5),$I18,0) -> 5583.3333 | Z18: =$H18/3*N18+IF(AND($E18<>"",$E18>=Z$4,$E18<=Z$5),$I18,0) -> 5583.3333 | AA18: =$H18/3*O18+IF(AND($E18<>"",$E18>=AA$4,$E18<=AA$5),$I18,0) -> 5583.3333 | AB18: =$H18/3*P18+IF(AND($E18<>"",$E18>=AB$4,$E18<=AB$5),$I18,0) -> 5583.3333 | AC18: =$H18/3*Q18+IF(AND($E18<>"",$E18>=AC$4,$E18<=AC$5),$I18,0) -> 5583.3333 | ... AG18: =$H18/3*U18+IF(AND($E18<>"",$E18>=AG$4,$E18<=AG$5),$I18,0) -> 5583.3333 | AH18: =SUM(V18:AG18) -> 67000
A19: R12 | B19: Billing & Invoicing Expert | C19: Billing & Invoicing | D19: Spain · cross-country · Core team | E19: 46478 | G19: 1 | H19: 10385 | I19: 0 | J19: =IF($E19="",0,$G19*MAX(0,MIN(J$5,IF($F19="",J$5,$F19))-MAX(J$4,$E19)+1)/(J$5-J$4+1)) -> 0 | K19: =IF($E19="",0,$G19*MAX(0,MIN(K$5,IF($F19="",K$5,$F19))-MAX(K$4,$E19)+1)/(K$5-K$4+1)) -> 0 | L19: =IF($E19="",0,$G19*MAX(0,MIN(L$5,IF($F19="",L$5,$F19))-MAX(L$4,$E19)+1)/(L$5-L$4+1)) -> 0 | M19: =IF($E19="",0,$G19*MAX(0,MIN(M$5,IF($F19="",M$5,$F19))-MAX(M$4,$E19)+1)/(M$5-M$4+1)) -> 1 | N19: =IF($E19="",0,$G19*MAX(0,MIN(N$5,IF($F19="",N$5,$F19))-MAX(N$4,$E19)+1)/(N$5-N$4+1)) -> 1 | O19: =IF($E19="",0,$G19*MAX(0,MIN(O$5,IF($F19="",O$5,$F19))-MAX(O$4,$E19)+1)/(O$5-O$4+1)) -> 1 | P19: =IF($E19="",0,$G19*MAX(0,MIN(P$5,IF($F19="",P$5,$F19))-MAX(P$4,$E19)+1)/(P$5-P$4+1)) -> 1 | Q19: =IF($E19="",0,$G19*MAX(0,MIN(Q$5,IF($F19="",Q$5,$F19))-MAX(Q$4,$E19)+1)/(Q$5-Q$4+1)) -> 1 | ... U19: =IF($E19="",0,$G19*MAX(0,MIN(U$5,IF($F19="",U$5,$F19))-MAX(U$4,$E19)+1)/(U$5-U$4+1)) -> 1 | V19: =$H19/3*J19+IF(AND($E19<>"",$E19>=V$4,$E19<=V$5),$I19,0) -> 0 | W19: =$H19/3*K19+IF(AND($E19<>"",$E19>=W$4,$E19<=W$5),$I19,0) -> 0 | X19: =$H19/3*L19+IF(AND($E19<>"",$E19>=X$4,$E19<=X$5),$I19,0) -> 0 | Y19: =$H19/3*M19+IF(AND($E19<>"",$E19>=Y$4,$E19<=Y$5),$I19,0) -> 3461.6667 | Z19: =$H19/3*N19+IF(AND($E19<>"",$E19>=Z$4,$E19<=Z$5),$I19,0) -> 3461.6667 | AA19: =$H19/3*O19+IF(AND($E19<>"",$E19>=AA$4,$E19<=AA$5),$I19,0) -> 3461.6667 | AB19: =$H19/3*P19+IF(AND($E19<>"",$E19>=AB$4,$E19<=AB$5),$I19,0) -> 3461.6667 | AC19: =$H19/3*Q19+IF(AND($E19<>"",$E19>=AC$4,$E19<=AC$5),$I19,0) -> 3461.6667 | ... AG19: =$H19/3*U19+IF(AND($E19<>"",$E19>=AG$4,$E19<=AG$5),$I19,0) -> 3461.6667 | AH19: =SUM(V19:AG19) -> 31155
A20: R13 | B20: Operation Excellence Manager | C20: Operations & Service | D20: Spain · cross-country · Optimization Team / Direct Report to COO · hired via agency (20% of salary) | E20: 46388 | G20: 1 | H20: 18425 | I20: 11000 | J20: =IF($E20="",0,$G20*MAX(0,MIN(J$5,IF($F20="",J$5,$F20))-MAX(J$4,$E20)+1)/(J$5-J$4+1)) -> 1 | K20: =IF($E20="",0,$G20*MAX(0,MIN(K$5,IF($F20="",K$5,$F20))-MAX(K$4,$E20)+1)/(K$5-K$4+1)) -> 1 | L20: =IF($E20="",0,$G20*MAX(0,MIN(L$5,IF($F20="",L$5,$F20))-MAX(L$4,$E20)+1)/(L$5-L$4+1)) -> 1 | M20: =IF($E20="",0,$G20*MAX(0,MIN(M$5,IF($F20="",M$5,$F20))-MAX(M$4,$E20)+1)/(M$5-M$4+1)) -> 1 | N20: =IF($E20="",0,$G20*MAX(0,MIN(N$5,IF($F20="",N$5,$F20))-MAX(N$4,$E20)+1)/(N$5-N$4+1)) -> 1 | O20: =IF($E20="",0,$G20*MAX(0,MIN(O$5,IF($F20="",O$5,$F20))-MAX(O$4,$E20)+1)/(O$5-O$4+1)) -> 1 | P20: =IF($E20="",0,$G20*MAX(0,MIN(P$5,IF($F20="",P$5,$F20))-MAX(P$4,$E20)+1)/(P$5-P$4+1)) -> 1 | Q20: =IF($E20="",0,$G20*MAX(0,MIN(Q$5,IF($F20="",Q$5,$F20))-MAX(Q$4,$E20)+1)/(Q$5-Q$4+1)) -> 1 | ... U20: =IF($E20="",0,$G20*MAX(0,MIN(U$5,IF($F20="",U$5,$F20))-MAX(U$4,$E20)+1)/(U$5-U$4+1)) -> 1 | V20: =$H20/3*J20+IF(AND($E20<>"",$E20>=V$4,$E20<=V$5),$I20,0) -> 17141.667 | W20: =$H20/3*K20+IF(AND($E20<>"",$E20>=W$4,$E20<=W$5),$I20,0) -> 6141.6667 | X20: =$H20/3*L20+IF(AND($E20<>"",$E20>=X$4,$E20<=X$5),$I20,0) -> 6141.6667 | Y20: =$H20/3*M20+IF(AND($E20<>"",$E20>=Y$4,$E20<=Y$5),$I20,0) -> 6141.6667 | Z20: =$H20/3*N20+IF(AND($E20<>"",$E20>=Z$4,$E20<=Z$5),$I20,0) -> 6141.6667 | AA20: =$H20/3*O20+IF(AND($E20<>"",$E20>=AA$4,$E20<=AA$5),$I20,0) -> 6141.6667 | AB20: =$H20/3*P20+IF(AND($E20<>"",$E20>=AB$4,$E20<=AB$5),$I20,0) -> 6141.6667 | AC20: =$H20/3*Q20+IF(AND($E20<>"",$E20>=AC$4,$E20<=AC$5),$I20,0) -> 6141.6667 | ... AG20: =$H20/3*U20+IF(AND($E20<>"",$E20>=AG$4,$E20<=AG$5),$I20,0) -> 6141.6667 | AH20: =SUM(V20:AG20) -> 84700
J21: =IF($E21="",0,$G21*MAX(0,MIN(J$5,IF($F21="",J$5,$F21))-MAX(J$4,$E21)+1)/(J$5-J$4+1)) -> 0 | K21: =IF($E21="",0,$G21*MAX(0,MIN(K$5,IF($F21="",K$5,$F21))-MAX(K$4,$E21)+1)/(K$5-K$4+1)) -> 0 | L21: =IF($E21="",0,$G21*MAX(0,MIN(L$5,IF($F21="",L$5,$F21))-MAX(L$4,$E21)+1)/(L$5-L$4+1)) -> 0 | M21: =IF($E21="",0,$G21*MAX(0,MIN(M$5,IF($F21="",M$5,$F21))-MAX(M$4,$E21)+1)/(M$5-M$4+1)) -> 0 | N21: =IF($E21="",0,$G21*MAX(0,MIN(N$5,IF($F21="",N$5,$F21))-MAX(N$4,$E21)+1)/(N$5-N$4+1)) -> 0 | O21: =IF($E21="",0,$G21*MAX(0,MIN(O$5,IF($F21="",O$5,$F21))-MAX(O$4,$E21)+1)/(O$5-O$4+1)) -> 0 | P21: =IF($E21="",0,$G21*MAX(0,MIN(P$5,IF($F21="",P$5,$F21))-MAX(P$4,$E21)+1)/(P$5-P$4+1)) -> 0 | Q21: =IF($E21="",0,$G21*MAX(0,MIN(Q$5,IF($F21="",Q$5,$F21))-MAX(Q$4,$E21)+1)/(Q$5-Q$4+1)) -> 0 | ... U21: =IF($E21="",0,$G21*MAX(0,MIN(U$5,IF($F21="",U$5,$F21))-MAX(U$4,$E21)+1)/(U$5-U$4+1)) -> 0 | V21: =$H21/3*J21+IF(AND($E21<>"",$E21>=V$4,$E21<=V$5),$I21,0) -> 0 | W21: =$H21/3*K21+IF(AND($E21<>"",$E21>=W$4,$E21<=W$5),$I21,0) -> 0 | X21: =$H21/3*L21+IF(AND($E21<>"",$E21>=X$4,$E21<=X$5),$I21,0) -> 0 | Y21: =$H21/3*M21+IF(AND($E21<>"",$E21>=Y$4,$E21<=Y$5),$I21,0) -> 0 | Z21: =$H21/3*N21+IF(AND($E21<>"",$E21>=Z$4,$E21<=Z$5),$I21,0) -> 0 | AA21: =$H21/3*O21+IF(AND($E21<>"",$E21>=AA$4,$E21<=AA$5),$I21,0) -> 0 | AB21: =$H21/3*P21+IF(AND($E21<>"",$E21>=AB$4,$E21<=AB$5),$I21,0) -> 0 | AC21: =$H21/3*Q21+IF(AND($E21<>"",$E21>=AC$4,$E21<=AC$5),$I21,0) -> 0 | ... AG21: =$H21/3*U21+IF(AND($E21<>"",$E21>=AG$4,$E21<=AG$5),$I21,0) -> 0 | AH21: =SUM(V21:AG21) -> 0
